Workbook

Sheet Empresas
A1: # | B1: Empresa | C1: Categoría | D1: Perfil ciclo | E1: Dirección (Zaragoza) | F1: Teléfono | G1: Web | H1: Prioridad | I1: Notas | J1: Estado convenio | K1: Tutor/a dual responsable | L1: Persona de contacto | M1: Fecha contacto | N1: Resultado / seguimiento
A2: 1 | B2: Aratecnia Sistemas y Servicios | C2: Soporte IT empresas | D2: SMR/ASIR | E2: C. Pedro Villacampa 48, 50015 | F2: 976 52 45 84 | G2: aratecnia.es | H2: Alta | I2: Mantenimiento IT pymes | J2: Sin contactar
A3: 2 | B3: Goya Soluciones Informáticas | C3: Soporte IT empresas | D3: SMR/ASIR | E3: Av. Puente del Pilar 37, 50014 | F3: 976 30 28 58 | G3: goyasoluciones.com | H3: Alta | J3: Sin contactar
A4: 3 | B4: Informática Ingenia | C4: Soporte IT empresas | D4: SMR | E4: Camino de las Torres 4, 50002 | F4: 976 31 74 12 | G4: ingenia-aragon.es | H4: Alta | I4: Soporte hw/sw | J4: Sin contactar
A5: 4 | B5: OnSAT Servicios Informáticos | C5: Soporte IT empresas | D5: SMR/ASIR | E5: C. El Acorazado Potemkin 3, 50019 | F5: 976 79 20 41 | G5: onsat.es | H5: Alta | I5: SAT + consultoría | J5: Sin contactar
A6: 5 | B6: Albada Servicios Informáticos | C6: Soporte IT empresas | D6: SMR | E6: C. Miguel de Cervantes 24, 50006 | F6: 976 46 83 38 | G6: albada.es | H6: Alta | J6: Sin contactar
A7: 6 | B7: Tempus Informática | C7: Soporte IT empresas | D7: SMR/ASIR | E7: C. Reina Fabiola 37, of. 124, 50008 | F7: 976 59 16 07 | G7: tempus.es | H7: Alta | J7: Sin contactar
A8: 7 | B8: Carrie Servicios Informáticos | C8: Soporte IT empresas | D8: SMR | E8: C. Lastanosa 30, 50010 | F8: 976 30 02 48 | G8: carrieserviciosinformaticos.es | H8: Media | J8: Sin contactar
A9: 8 | B9: MEGASTAR | C9: Soporte IT empresas | D9: SMR | E9: Andador Paula Montal Fornés 4, 50018 | F9: 976 46 66 44 | G9: megastar.es | H9: Media | I9: Particulares y empresas | J9: Sin contactar
A10: 9 | B10: Informática Miranda Digital (Sage) | C10: Soporte IT empresas | D10: SMR/DAW | E10: Andador Paula Montal Fornés 4, 50018 | F10: 976 56 99 30 | G10: imdigital.es | H10: Media | I10: Partner Sage + web | J10: Sin contactar
A11: 10 | B11: iDoo Tech | C11: Soporte IT empresas | D11: SMR | E11: Av. Gómez Laguna 25, pl. 5, 50009 | F11: 976 91 01 30 | G11: idootech.com | H11: Media | I11: Apple / pymes | J11: Sin contactar
A12: 11 | B12: SolucionesDS | C12: Soporte IT empresas | D12: SMR | E12: C. Martín Carrillo 5, 50001 | F12: 976 46 80 69 | G12: solucionesds.es | H12: Media | I12: Partner Lenovo | J12: Sin contactar
A13: 12 | B13: Pernía Informática | C13: Soporte IT empresas | D13: SMR | E13: C. Dr. Iranzo 90, 50002 | F13: 976 13 37 91 | G13: perniasistemas.com | H13: Media | I13: Tienda + consultoría | J13: Sin contactar
A14: 13 | B14: Acosis | C14: Soporte IT empresas | D14: SMR/ASIR | E14: C. José Mª Lacarra de Miguel 40, 50008 | F14: 976 30 24 10 | H14: Alta | J14: Sin contactar
A15: 14 | B15: Aragonesa de Tecnología | C15: Soporte IT empresas | D15: SMR/ASIR | E15: Av. Valencia 28, pl. 6 of. 1, 50005 | F15: 976 42 93 73 | H15: Alta | J15: Sin contactar
A16: 15 | B16: Atlas Proyectos Informáticos | C16: Soporte IT empresas | D16: SMR/ASIR | E16: Av. Cesáreo Alierta 23-25, of. 113-114, 50008 | F16: 976 59 08 45 | H16: Alta | I16: SAP Business One + soporte | J16: Sin contactar
A17: 16 | B17: ZILON Informática para empresas | C17: Soporte IT empresas | D17: SMR | E17: C. Añón 18, 50002 | F17: 633 32 44 00 | H17: Media | J17: Sin contactar
A18: 17 | B18: Infoelite | C18: Soporte IT empresas | D18: SMR | E18: C. Adolfo Aznar 28, 50018 | F18: 976 74 21 43 | H18: Media | J18: Sin contactar
A19: 18 | B19: Visualcom Soluciones Informáticas | C19: Soporte IT empresas | D19: SMR | E19: C. Felisa Galé 1, 50014 | F19: 976 25 90 99 | H19: Media | I19: Mismo grupo que Ahora Express / Zierzo | J19: Sin contactar
A20: 19 | B20: ACCIONET | C20: Soporte IT empresas | D20: SMR/ASIR | E20: C. Francisco Rallo Lahoz 29, 1ºD, 50011 | F20: 976 37 39 73 | H20: Media | I20: Servicios TIC | J20: Sin contactar
A21: 20 | B21: eMenntun | C21: Soporte IT empresas | D21: SMR | E21: C. Coso 102, entlo. of. 4, 50001 | F21: 646 81 07 61 | H21: Baja | I21: Unipersonal, formación | J21: Sin contactar
A22: 21 | B22: Planea Soluciones | C22: Soporte IT empresas | D22: SMR/DAW | E22: C. San Agustín 8, 50002 | F22: 876 66 10 10 | H22: Media | I22: Web + email + soporte | J22: Sin contactar
A23: 22 | B23: Arona Systems | C23: Redes y telecomunicaciones | D23: SMR/ASIR | E23: C. Ntra. Sra. de Covadonga 18-20, 50017 | F23: 976 39 41 55 | G23: aronasystems.com | H23: Alta | I23: Cableado estructurado | J23: Sin contactar
A24: 23 | B24: Sincronet Security & Networking | C24: Redes y ciberseguridad | D24: SMR/ASIR | E24: C. Ibón de Estanés 10, 50011 | F24: 976 46 76 21 | G24: sincronet.es | H24: Alta | J24: Sin contactar
A25: 24 | B25: ZADITEL | C25: Redes y telecomunicaciones | D25: SMR/ASIR | E25: C. José Donoso 13, 50018 | F25: 976 79 99 99 | G25: zaditel.com | H25: Alta | J25: Sin contactar
A26: 25 | B26: Balui Digital | C26: Redes y ciberseguridad | D26: SMR/DAW | E26: C. Miquel Roca i Junyent 7, pl. 2, 50011 | F26: 976 36 23 23 | G26: baluidigital.es | H26: Media | I26: Ciberseguridad, web, TPV | J26: Sin contactar
A27: 26 | B27: Ciberseguridad Gobernada (Cibergob) | C27: Redes y ciberseguridad | D27: ASIR | E27: Ed. Náyade, C. Bari 55, of. 211, PLAZA 50197 | F27: 876 64 66 15 | G27: cibergob.es | H27: Media | J27: Sin contactar
A28: 27 | B28: Zierzo Telecom | C28: Redes y telecomunicaciones | D28: SMR | E28: C. Felisa Galé 1, 50014 | F28: 876 66 11 50 | H28: Media | I28: Operador local | J28: Sin contactar
A29: 28 | B29: Grupo Soastel | C29: Redes y telecomunicaciones | D29: SMR | E29: Pol. Malpica, C. F parc. 57 nave 20, 50016 | F29: 976 79 91 91 | H29: Media | J29: Sin contactar
A30: 29 | B30: Embou (MásMóvil) | C30: Redes y telecomunicaciones | D30: SMR/ASIR | E30: Av. Juan Pablo II 35, 50009 | F30: 622 48 42 19 | G30: embou.com | H30: Media | I30: Operador aragonés, sede corporativa | J30: Sin contactar
A31: 30 | B31: La Casa de la Fibra | C31: Redes y telecomunicaciones | D31: SMR | E31: C. Compromiso de Caspe 107, 50002 | F31: 876 03 02 00 | H31: Baja | I31: Operador local | J31: Sin contactar
A32: 31 | B32: Finetwork Zaragoza Goya | C32: Redes y telecomunicaciones | D32: SMR | E32: Av. Goya 96, 50005 | F32: 876 01 57 66 | H32: Baja | I32: Tienda operador | J32: Sin contactar
A33: 32 | B33: Libelium | C33: Redes y telecomunicaciones | D33: ASIR/DAM | E33: C. María Zambrano 31, torre este pl. 7, 50018 | F33: 976 54 74 92 | G33: libelium.com | H33: Media | I33: IoT | J33: Sin contactar
A34: 33 | B34: Hiberus | C34: Consultora / gran empresa | D34: SMR/ASIR/DAM/DAW | E34: Pº Isabel la Católica 6, 50009 | F34: 976 10 66 20 | G34: hiberus.com | H34: Alta | I34: Mayor empleador TIC de Aragón; tiene helpdesk | J34: Sin contactar
A35: 34 | B35: Hiberus Booster (antes Factory Apps) | C35: Consultora / gran empresa | D35: DAM/DAW | E35: Pº Isabel la Católica 6, 50009 | G35: hiberusbooster.com | H35: Media | I35: Desarrollo apps | J35: Sin contactar
A36: 35 | B36: Inycom | C36: Consultora / gran empresa | D36: SMR/ASIR/DAM | E36: PLAZA, C. Alaún 8, 50197 | F36: 976 01 33 00 | G36: inycom.es | H36: Alta | I36: Servicios TI + electromedicina | J36: Sin contactar
A37: 36 | B37: NTT DATA (everis Aragón) | C37: Consultora / gran empresa | D37: DAM/DAW/ASIR | E37: Pl. Antonio Beltrán Martínez 1, pl. 9, 50002 | F37: 976 48 20 80 | G37: nttdata.com | H37: Alta | I37: Oficina Aragonia: Av. Juan Pablo II 35, pl. 6 | J37: Sin contactar
A38: 37 | B38: Capgemini Zaragoza | C38: Consultora / gran empresa | D38: DAM/DAW/ASIR | E38: C. Eduardo Ibarra 6, of. 2.4, 50009 | F38: 912 15 37 00 | G38: capgemini.com | H38: Media | J38: Sin contactar
A39: 38 | B39: Deloitte Zaragoza | C39: Consultora / gran empresa | D39: DAM/DAW | E39: C. María Zambrano 31, torre oeste pl. 16, 50018 | F39: 976 21 46 75 | G39: deloitte.com | H39: Media | I39: Área tecnología | J39: Sin contactar
A40: 39 | B40: Indra Sistemas Zaragoza | C40: Consultora / gran empresa | D40: DAM/ASIR | E40: C. María Zambrano 31, 50018 | F40: 914 80 50 00 | G40: indracompany.com | H40: Media | J40: Sin contactar
...

Sheet Resumen
A1: Resumen prospección
A3: Categoría | B3: Nº empresas | C3: Convenio firmado
A4: Consultora / gran empresa | B4: =COUNTIF(Empresas!$C$2:$C$97,A4) -> 22 | C4: =COUNTIFS(Empresas!$C$2:$C$97,A4,Empresas!$J$2:$J$97,"Convenio firmado") -> 0
A5: Desarrollo software | B5: =COUNTIF(Empresas!$C$2:$C$97,A5) -> 22 | C5: =COUNTIFS(Empresas!$C$2:$C$97,A5,Empresas!$J$2:$J$97,"Convenio firmado") -> 0
A6: Distribución / mayorista | B6: =COUNTIF(Empresas!$C$2:$C$97,A6) -> 3 | C6: =COUNTIFS(Empresas!$C$2:$C$97,A6,Empresas!$J$2:$J$97,"Convenio firmado") -> 0
A7: Organismo público / I+D | B7: =COUNTIF(Empresas!$C$2:$C$97,A7) -> 3 | C7: =COUNTIFS(Empresas!$C$2:$C$97,A7,Empresas!$J$2:$J$97,"Convenio firmado") -> 0
A8: Redes y ciberseguridad | B8: =COUNTIF(Empresas!$C$2:$C$97,A8) -> 3 | C8: =COUNTIFS(Empresas!$C$2:$C$97,A8,Empresas!$J$2:$J$97,"Convenio firmado") -> 0
A9: Redes y telecomunicaciones | B9: =COUNTIF(Empresas!$C$2:$C$97,A9) -> 8 | C9: =COUNTIFS(Empresas!$C$2:$C$97,A9,Empresas!$J$2:$J$97,"Convenio firmado") -> 0
A10: Soporte IT empresas | B10: =COUNTIF(Empresas!$C$2:$C$97,A10) -> 21 | C10: =COUNTIFS(Empresas!$C$2:$C$97,A10,Empresas!$J$2:$J$97,"Convenio firmado") -> 0
A11: Tienda / reparación | B11: =COUNTIF(Empresas!$C$2:$C$97,A11) -> 14 | C11: =COUNTIFS(Empresas!$C$2:$C$97,A11,Empresas!$J$2:$J$97,"Convenio firmado") -> 0
A12: TOTAL | B12: =SUM(B4:B11) -> 96 | C12: =SUM(C4:C11) -> 0
A14: Estado | B14: Nº
A15: Sin contactar | B15: =COUNTIF(Empresas!$J$2:$J$97,A15) -> 96
A16: Contactado | B16: =COUNTIF(Empresas!$J$2:$J$97,A16) -> 0
A17: Interesada | B17: =COUNTIF(Empresas!$J$2:$J$97,A17) -> 0
A18: Convenio firmado | B18: =COUNTIF(Empresas!$J$2:$J$97,A18) -> 0
A19: Rechazada | B19: =COUNTIF(Empresas!$J$2:$J$97,A19) -> 0
A21: Leyenda: celdas amarillas de la hoja Empresas son las de seguimiento a rellenar. Fuente del listado: Google Maps (sept. 2026) + empresas TIC conocidas de Zaragoza; verificar teléfonos y direcciones antes de firmar convenio.
